Workbook

Sheet AHP Dataset
A1: Komunikasi vs Sumber Daya | B1: Komunikasi vs Disposisi | C1: Komunikasi vs Struktur Birokrasi | D1: Sumber Daya vs Disposisi | E1: Sumber Daya vs Struktur Birokrasi | F1: Disposisi vs Struktur Birokrasi
A2: Sama penting (1) | B2: Sama penting (1) | C2: Komunikasi lebih penting (7) | D2: Sumber Daya lebih penting (7) | E2: Sumber Daya lebih penting (7) | F2: Sama penting (1)
A3: Komunikasi sangat jauh lebih penting (9) | B3: Komunikasi sangat jauh lebih penting (9) | C3: Komunikasi sangat jauh lebih penting (9) | D3: Sumber Daya sangat jauh lebih penting (9) | E3: Sumber Daya lebih penting (7) | F3: Disposisi sedikit lebih penting (3)
A4: Komunikasi lebih penting (7) | B4: Sama penting (1) | C4: Komunikasi sedikit lebih penting (3) | D4: Sama penting (1) | E4: Struktur Birokrasi sedikit lebih penting (1/3) | F4: Sama penting (1)
A5: Komunikasi agak lebih penting (5) | B5: Komunikasi lebih penting (7) | C5: Komunikasi lebih penting (7) | D5: Sumber Daya lebih penting (7) | E5: Sumber Daya sangat jauh lebih penting (9) | F5: Disposisi lebih penting (7)
A6: Sumber Daya sangat jauh lebih penting (1/9) | B6: Disposisi sangat jauh lebih penting (1/9) | C6: Struktur Birokrasi sangat jauh lebih penting (1/9) | D6: Sumber Daya sangat jauh lebih penting (9) | E6: Sumber Daya sangat jauh lebih penting (9) | F6: Disposisi sangat jauh lebih penting (9)
A7: Komunikasi sangat jauh lebih penting (9) | B7: Komunikasi sangat jauh lebih penting (9) | C7: Komunikasi sangat jauh lebih penting (9) | D7: Sumber Daya sangat jauh lebih penting (9) | E7: Sumber Daya sangat jauh lebih penting (9) | F7: Struktur Birokrasi sangat jauh lebih penting (1/9)
A8: Sama penting (1) | B8: Komunikasi lebih penting (7) | C8: Komunikasi lebih penting (7) | D8: Sumber Daya lebih penting (7) | E8: Sumber Daya lebih penting (7) | F8: Struktur Birokrasi lebih penting (1/7)
A9: Komunikasi sedikit lebih penting (3) | B9: Komunikasi agak lebih penting (5) | C9: Sama penting (1) | D9: Sama penting (1) | E9: Sumber Daya sedikit lebih penting (3) | F9: Disposisi sedikit lebih penting (3)
A10: Komunikasi sangat jauh lebih penting (9) | B10: Komunikasi sangat jauh lebih penting (9) | C10: Komunikasi sedikit lebih penting (3) | D10: Sumber Daya sangat jauh lebih penting (9) | E10: Sumber Daya lebih penting (7) | F10: Disposisi sangat jauh lebih penting (9)
A11: Sumber Daya sangat jauh lebih penting (1/9) | B11: Komunikasi sangat jauh lebih penting (9) | C11: Komunikasi sangat jauh lebih penting (9) | D11: Sumber Daya sangat jauh lebih penting (9) | E11: Sumber Daya sangat jauh lebih penting (9) | F11: Disposisi sangat jauh lebih penting (9)
A12: Sama penting (1) | B12: Sama penting (1) | C12: Sama penting (1) | D12: Sama penting (1) | E12: Sama penting (1) | F12: Sama penting (1)
... A1204: Sama penting (1) | B1204: Disposisi sedikit lebih penting (1/3) | C1204: Komunikasi sedikit lebih penting (3) | D1204: Disposisi sedikit lebih penting (1/3) | E1204: Sumber Daya agak lebih penting (5) | F1204: Disposisi agak lebih penting (5)

Sheet Dataset
A1: Nama | B1: Jabatan | C1: Komunikasi vs Sumber Daya | D1: Komunikasi vs Disposisi | E1: Komunikasi vs Struktur Birokrasi | F1: Sumber Daya vs Disposisi | G1: Sumber Daya vs Struktur Birokrasi | H1: Disposisi vs Struktur Birokrasi | I1: Jenis Kelamin | J1: No. Telephon/Whatsapp* | K1: Asal Kota/Kabupaten | L1: Sejauh mana komunikasi yang efektif antara pemerintah, industri, dan masyarakat mempengaruhi keberhasilan implementasi JPH di Indonesia? | M1: Sejauh mana ketersediaan sumber daya, seperti dana dan tenaga ahli, mempengaruhi implementasi JPH? | N1: Sejauh mana disposisi atau komitmen dari para pemangku kepentingan (pemerintah dan industri) mempengaruhi implementasi JPH? | O1: Apa tantangan terbesar yang Anda hadapi dalam implementasi JPH di Indonesia terkait dengan komunikasi, sumber daya, disposisi, dan struktur birokrasi? | P1: Sejauh mana struktur birokrasi yang efisien dan jelas mendukung implementasi JPH? | Q1: Apakah Anda merasa bahwa faktor-faktor tertentu lebih penting daripada yang lain dalam konteks implementasi JPH di Indonesia? Jika ya, jelaskan mengapa. | R1: Apakah ada faktor lain yang menurut Anda juga mempengaruhi keberhasilan implementasi JPH, namun tidak tercakup dalam kriteria di atas? | S1: Lama Pengalaman dalam Implementasi JPH | T1: Provinsi | U1: Jenis Produk Industri/UMKM (Jika dari Pelaku Usaha) | V1: Pendidikan Terakhir | W1: Penilaian Kriteria Berpasangan
A2: Sugeng ribowo | B2: Kepala | C2: Sama penting (1) | D2: Sama penting (1) | E2: Komunikasi lebih penting (7) | F2: Sumber Daya lebih penting (7) | G2: Sumber Daya lebih penting (7) | H2: Sama penting (1)
A3: UMKM | B3: Pelaku usaha | C3: Komunikasi sangat jauh lebih penting (9) | D3: Komunikasi sangat jauh lebih penting (9) | E3: Komunikasi sangat jauh lebih penting (9) | F3: Sumber Daya sangat jauh lebih penting (9) | G3: Sumber Daya lebih penting (7) | H3: Disposisi sedikit lebih penting (3) | I3: Laki-laki | K3: Bogor | L3: Netral | M3: Sangat Tidak Penting | N3: Tidak Penting | P3: Netral | S3: 0-5 tahun
A4: Indiah | B4: Pembina Industri | C4: Komunikasi lebih penting (7) | D4: Sama penting (1) | E4: Komunikasi sedikit lebih penting (3) | F4: Sama penting (1) | G4: Struktur Birokrasi sedikit lebih penting (1/3) | H4: Sama penting (1) | I4: Perempuan | K4: Yogyakarta | L4: Sangat Penting | M4: Penting | N4: Penting | O4: Komunikasi | P4: Sangat Penting | Q4: Komunikasi agar seluruh lapisan memahami regulasi tersebut. | R4: Suara konsumen terkait kebutuhan Halal | S4: 1,5 -2 tahun | T4: DI Yogyakarta | U4: - | V4: S2
A5: Alim Mahawan Nuryadi | B5: Pembina Industri | C5: Komunikasi agak lebih penting (5) | D5: Komunikasi lebih penting (7) | E5: Komunikasi lebih penting (7) | F5: Sumber Daya lebih penting (7) | G5: Sumber Daya sangat jauh lebih penting (9) | H5: Disposisi lebih penting (7) | I5: Laki-laki | K5: Manado | L5: Sangat Penting | M5: Sangat Penting | N5: Sangat Penting | O5: Disposisi pemangku kepentingan dapat merubah ego sektoral dari berbagai pihak yang memiliki kepentingan yang berbeda. | P5: Sangat Penting | Q5: Faktor Disposisi menjadikan kepentingan yg berbeda disetiap elemen masyarakat | S5: > 3 tahun | T5: Sulawesi Utara | U5: Bukan PU | V5: S2
A6: Fitriana Djafar | B6: AMMI Ahli Madya/ Auditor Halal | C6: Sumber Daya sangat jauh lebih penting (1/9) | D6: Disposisi sangat jauh lebih penting (1/9) | E6: Struktur Birokrasi sangat jauh lebih penting (1/9) | F6: Sumber Daya sangat jauh lebih penting (9) | G6: Sumber Daya sangat jauh lebih penting (9) | H6: Disposisi sangat jauh lebih penting (9) | I6: Perempuan | K6: Kota Banda Aceh | L6: Penting | M6: Sangat Penting | N6: Sangat Penting | O6: Sumber daya adalah tantangan terbesar dalam implementasi JPH di Indonesia karena faktor ini merupakan pondasi teknis dan operasional dari implementasi JPH. Tanpa sumber daya (tenaga ahli, dana, fasilitas, dan teknologi), kebijakan tidak bisa dijalankan meskipun komunikasi baik dan birokrasi mendukung. | P6: Sangat Penting | Q6: Ke empat faktor tersebut saling terkait satu dan lainnya, namun dalam konteks implementasi bilamana dilakukan urutan berdasarkan prioritas faktor yang lebih penting yaitu sebagai berikut: 1).sumber daya; 2) disposisi, 3)struktur birokrasi dan 4) komunikasi | R6: Ya, terdapat faktor lainnya yang juga signifikan mempengaruhi implementasi JPH, antara lain : 1) Budaya, Kesadaran dan Persepsi Masyarakat (terutama konsumen dan Pelaku Usaha); 2) Peraturan Turunan (spt: PP, Permen, dan SOP teknis) yang jelas dan konsisten) serta skema dan standar audit halal yang jelas dan terinci; 3) Dukungan Teknologi/Sistem Digital yang responsif dan akuntable/aplikasi tidak lambat/tidak sering eror/; 4) Peran pihak swasta/ industri dan atau pihak Fasilitator dalam hal edukasi halal, pembiayaan sertifikasi halal dan pendampingan UMKM; dan 5) Faktor ekonomi dan beban biaya sertifikasi halal (UMKM terbebani biaya terutama jika tidak ada subsidi/ diskon/ program fasilitasi). | S6: 2,5 -3 tahun | T6: Aceh | U6: *Bukan Pelaku Usaha | V6: S2
A7: Muhammad Reza | B7: Direktur | C7: Komunikasi sangat jauh lebih penting (9) | D7: Komunikasi sangat jauh lebih penting (9) | E7: Komunikasi sangat jauh lebih penting (9) | F7: Sumber Daya sangat jauh lebih penting (9) | G7: Sumber Daya sangat jauh lebih penting (9) | H7: Struktur Birokrasi sangat jauh lebih penting (1/9) | I7: Laki-laki | K7: Bulukumba | L7: Sangat Penting | M7: Sangat Penting | N7: Sangat Penting | O7: Tidak ada | P7: Sangat Penting | Q7: Tidak ada | R7: Tidak ada | S7: 1 tahun | T7: Sulawesi Selatan | U7: Air Minum Kemasan | V7: SMA
A8: Yudo Purnomo | B8: PMB Madya | C8: Sama penting (1) | D8: Komunikasi lebih penting (7) | E8: Komunikasi lebih penting (7) | F8: Sumber Daya lebih penting (7) | G8: Sumber Daya lebih penting (7) | H8: Struktur Birokrasi lebih penting (1/7) | I8: Laki-laki | K8: Padang | L8: Sangat Penting | M8: Penting | N8: Netral | O8: Diperlukan peran aktif pemerintah dan stakeholder terkait untuk lebih menyebarkan pentingnya sertifikasi kehalalan produk | P8: Penting | Q8: Iya, terutama komunikasi dan SDM. Dikarenakan komunikasi yg baik akan mempercepat tersebarnya informasi tentang SH. Dan SDM yang baik juga akan lebih mengakselerasi penyebaran informasi | R8: Terkait partisipasi masyarakat. Masih kurangnya partisipasi aktif masyarakar dalam melakukan SH produknya | S8: 2,5 -3 tahun | T8: Sumatera Barat | U8: Layanan jasa industri | V8: S2
A9: Novreza Utama Putra | B9: Pembina Industri | C9: Komunikasi sedikit lebih penting (3) | D9: Komunikasi agak lebih penting (5) | E9: Sama penting (1) | F9: Sama penting (1) | G9: Sumber Daya sedikit lebih penting (3) | H9: Disposisi sedikit lebih penting (3) | I9: Laki-laki | K9: Bekasi | L9: Netral | M9: Penting | N9: Penting | O9: Penyebaran informasi tentang JPH terhadap masyarakat masih sangat minim tersampaikan, perlu adanya strategi jitu dalam memberikan edukasi kepada masyarakat. | P9: Penting | Q9: Tidak | R9: Tingkat keyakinan spritual masing-masing individu tentang halal. | S9: > 3 tahun | T9: Jawa Barat | U9: Government | V9: S2
A10: Muhammad Alvian Caesar | B10: Pelajar | C10: Komunikasi sangat jauh lebih penting (9) | D10: Komunikasi sangat jauh lebih penting (9) | E10: Komunikasi sedikit lebih penting (3) | F10: Sumber Daya sangat jauh lebih penting (9) | G10: Sumber Daya lebih penting (7) | H10: Disposisi sangat jauh lebih penting (9) | I10: Laki-laki | K10: Kab Demak | L10: Penting | M10: Penting | N10: Penting | O10: Komunikassi,Sumber daya,Disposisi, strukrur birokrasi | P10: Penting | Q10: Ya, dalam konteks implementasi Jaminan Produk Halal (JPH) di Indonesia, faktor sumber daya dapat dikatakan lebih penting daripada faktor lainnya — meskipun semua faktor saling berkaitan. Berikut penjelasan mengapa sumber daya menjadi faktor paling krusial: Sumber daya merupakan fondasi dari semua faktor lainnya. Tanpa SDM yang kompeten, auditor yang cukup, penyelia yang terlatih, dan dukungan fasilitas, maka komunikasi, niat baik, dan perbaikan birokrasi tidak akan cukup mendorong suksesnya implementasi JPH. Namun demikian, keberhasilan implementasi JPH tetap membutuhkan sinergi antar seluruh faktor, bukan berdiri sendiri. | R10: Faktor-faktor di luar komunikasi, sumber daya, disposisi, dan struktur birokrasi yang juga sangat memengaruhi keberhasilan JPH adalah: 1. Kesadaran masyarakat 2. Penegakan hukum dan regulasi 3. Teknologi dan infrastruktur 4. Peran pendamping/ormas 5. Transparansi bahan baku > Semua faktor tersebut berperan sebagai pendukung sistemik yang jika diabaikan, akan menghambat implementasi JPH meskipun struktur formalnya sudah dibangun. | S10: 2,5 -3 tahun | T10: Jawa Tengah | U10: Peyek Mbok Marti | V10: SMA
A11: Pujianto | B11: Pemilik | C11: Sumber Daya sangat jauh lebih penting (1/9) | D11: Komunikasi sangat jauh lebih penting (9) | E11: Komunikasi sangat jauh lebih penting (9) | F11: Sumber Daya sangat jauh lebih penting (9) | G11: Sumber Daya sangat jauh lebih penting (9) | H11: Disposisi sangat jauh lebih penting (9) | I11: Laki-laki | K11: Kabupaten Semarang | L11: Sangat Penting | M11: Sangat Penting | N11: Sangat Penting | O11: Ada beberapa hal ya g kami hadapi yaitu kurangnya koordinasi dan transparansi dalam penyampaian informasi termasuk dalam perizinan dan pengawasan serta keterbatasan SDM dan anggaran serta sistem yang tidak terintegrasi | P11: Sangat Penting | Q11: Tidak...semua faktor diatas sudah mencakup dalam pendukung implementasi JPH tersebut | R11: Mungkin sering diadakan bimbingan teknis ke lokasi agar mudah dipahami | S11: 1 tahun | T11: Jawa Tengah | U11: Keripik | V11: S1
A12: Siti khotimah | B12: Pimpinan | C12: Sama penting (1) | D12: Sama penting (1) | E12: Sama penting (1) | F12: Sama penting (1) | G12: Sama penting (1) | H12: Sama penting (1) | I12: Perempuan | K12: Demak | L12: Sangat Penting | M12: Sangat Penting | N12: Sangat Penting | P12: Sangat Penting | Q12: ya | R12: tidak ada | S12: 1-6 bulan | T12: Jawa tengah | U12: Sambel pecel kenangajaya | V12: S1
A13: Faisal Muin | B13: Direktur | C13: Komunikasi lebih penting (7) | D13: Komunikasi lebih penting (7) | E13: Komunikasi lebih penting (7) | F13: Sama penting (1) | G13: Sama penting (1) | H13: Sama penting (1) | I13: Laki-laki | K13: Pangkajene dan kepulauan | L13: Sangat Penting | M13: Sangat Penting | N13: Sangat Penting | O13: Meniyapkan atau mencari bahan baku yang sesuai dengan peraturan. | P13: Sangat Penting | Q13: Ya, agar konsumen lebih percaya atau yakin dengan produk yang kami tawarkan. | R13: Tidak ada, karena semua sudah dielaskan dengan sangat jelas. | S13: 2,5 -3 tahun | T13: Sulawesi Selatan | U13: Amdk | V13: SMA
A14: RITA ZULIANAWATI | B14: PEMILIK | C14: Sama penting (1) | D14: Sama penting (1) | E14: Sama penting (1) | F14: Sama penting (1) | G14: Sama penting (1) | H14: Sama penting (1) | I14: Perempuan | K14: DEMAK | L14: Sangat Penting | M14: Sangat Penting | N14: Sangat Penting | O14: Biaya, pemahaman dan kompleksitas regulasi | P14: Sangat Penting | Q14: Ya,karena komitmen dan tanggungjawab manajemen merupakan faktor terpenting disuatu lini perusahaan dan kebijakan halal harus diimplementasikan secara konsisten | R14: Ada..yaitu pemahaman dan kesadaran karyawan serta ketersediaan sumber daya serta dukungan eksternal | S14: 1 tahun | T14: JAWA TENGAH | U14: MAKANAN RINGAN SIAP SANTAP | V14: S1
A15: zainal Arifin | B15: Wirasawasta | C15: Komunikasi lebih penting (7) | D15: Sama penting (1) | E15: Struktur Birokrasisedikit lebih penting (1/3) | F15: Disposisi sedikit lebih penting (1/3) | G15: Struktur Birokrasi sedikit lebih penting (1/3) | H15: Struktur Birokrasi sedikit lebih penting (1/3) | I15: Laki-laki | K15: Pinrang | L15: Netral | M15: Tidak Penting | N15: Tidak Penting | P15: Netral | S15: 1-6 bulan | T15: Sulawesi selatan | U15: Bakso ayam , Bakso sapi . | V15: SMA
A16: HERMAN | B16: DIREKTUR | C16: Sama penting (1) | D16: Komunikasi lebih penting (7) | E16: Sama penting (1) | F16: Sumber Daya lebih penting (7) | G16: Sama penting (1) | H16: Sama penting (1) | I16: Laki-laki | K16: SINJAI | L16: Penting | M16: Penting | N16: Penting | O16: Kurang informasi | P16: Penting | Q16: Tidak | R16: Tidak | S16: 1-6 bulan | T16: SULAWESI SELATAN | U16: AMDK CUP | V16: SMP
A17: Sugira | B17: Pemilik | C17: Sama penting (1) | D17: Komunikasi lebih penting (7) | E17: Komunikasi sangat jauh lebih penting (9) | F17: Sumber Daya agak lebih penting (5) | G17: Sumber Daya sedikit lebih penting (3) | H17: Sama penting (1) | I17: Perempuan | K17: BONE | L17: Sangat Penting | M17: Sangat Penting | N17: Penting | O17: Dana | P17: Sangat Penting | Q17: Tidak | R17: Sudah tercakup semua | S17: > 3 tahun | T17: Sulawesi Selatan | U17: ABON IKAN dan Abon Ayam | V17: S1
A18: Novia Arizandy | B18: Pemilik Usaha | C18: Sama penting (1) | D18: Sama penting (1) | E18: Sama penting (1) | F18: Sama penting (1) | G18: Sama penting (1) | H18: Sama penting (1) | I18: Perempuan | K18: Watampone / Bone | L18: Sangat Penting | M18: Sangat Penting | N18: Sangat Penting | O18: - | P18: Sangat Penting | Q18: - | R18: - | S18: 1-6 bulan | T18: Sulawesi Selatan | U18: Abon | V18: SMA
A19: Fajri Haykal Ramadhan | B19: Karyawan swasta | C19: Sama penting (1) | D19: Komunikasi lebih penting (7) | E19: Struktur Birokrasisedikit lebih penting (1/3) | F19: Sumber Daya sangat jauh lebih penting (9) | G19: Sumber Daya sangat jauh lebih penting (9) | H19: Struktur Birokrasi sedikit lebih penting (1/3) | I19: Laki-laki | K19: Cianjur | L19: Penting | M19: Sangat Penting | N19: Penting | O19: Sumber daya karena masyarakar belum memahami produk halal | P19: Penting | Q19: Ya, inovasi dalam pengelolaan JOH sehingga produk lebih unggul | R19: Keterbukaan dan jg pengelolaan keuangan | S19: > 3 tahun | T19: Jawa barat | U19: Makanan | V19: S2
A20: Nadhia | B20: IRT | C20: Komunikasi lebih penting (7) | D20: Disposisi lebih penting (1/7) | E20: Komunikasi lebih penting (7) | F20: Disposisi agak lebih penting (1/5) | G20: Sumber Daya sangat jauh lebih penting (9) | H20: Sama penting (1) | I20: Perempuan | K20: Jember | L20: Netral | M20: Penting | N20: Netral | O20: Struktur birokrasi | P20: Penting | Q20: Semua penting | S20: 1-6 bulan | T20: Jateng | U20: Fashion | V20: S1
A21: Mardianah rusli | B21: Owner | C21: Sumber Daya sangat jauh lebih penting (1/9) | D21: Disposisi sangat jauh lebih penting (1/9) | E21: Struktur Birokrasilebih penting (1/7) | F21: Sumber Daya sangat jauh lebih penting (9) | G21: Sumber Daya agak lebih penting (5) | H21: Sama penting (1) | I21: Perempuan | K21: Wajo | L21: Sangat Penting | M21: Sangat Penting | N21: Sangat Penting | P21: Penting | S21: 1 tahun | T21: Sulawesi selatan | U21: Abon Sapi & Abon ayam. | V21: SMA
A22: zainal Arifin | B22: wirasawasta | C22: Komunikasi lebih penting (7) | D22: Sama penting (1) | E22: Sama penting (1) | F22: Sama penting (1) | G22: Sama penting (1) | H22: Sama penting (1) | I22: Laki-laki | K22: Pinrang | L22: Netral | M22: Netral | N22: Netral | O22: kesulitan dalam memastikan ketersediaan | P22: Netral | Q22: ya karna dukungan pemerintah lebih penting dalam mencapai penghasilan | R22: tdk ada, | S22: 1-6 bulan | T22: sulawesi selatan | U22: Bakso sapi , bkso ayam | V22: SMA
A23: JASLIN | B23: PELAKU USAHA | C23: Sumber Daya sangat jauh lebih penting (1/9) | D23: Komunikasi sangat jauh lebih penting (9) | E23: Komunikasi sangat jauh lebih penting (9) | F23: Sumber Daya sangat jauh lebih penting (9) | G23: Sumber Daya sangat jauh lebih penting (9) | H23: Disposisi sangat jauh lebih penting (9) | I23: Perempuan | K23: PINRANG | L23: Sangat Penting | M23: Sangat Penting | N23: Sangat Penting | P23: Sangat Penting | S23: 1-6 bulan | T23: SULAWESI SELATAN | U23: ABON | V23: SMP
A24: Pasha Anantha Apriliza | B24: Mahasiswa | C24: Komunikasi sangat jauh lebih penting (9) | D24: Sama penting (1) | E24: Sama penting (1) | F24: Sama penting (1) | G24: Sumber Daya sedikit lebih penting (3) | H24: Sama penting (1) | I24: Perempuan | K24: kab sukabumi | L24: Netral | M24: Sangat Penting | N24: Sangat Penting | O24: Tantangan terbesar dalam implementasi JPH di Indonesia adalah ketidaksiapan struktur birokrasi dan sumber daya, yang diperparah oleh komunikasi yang tidak efektif dan komitmen pelaksana yang belum merata. Untuk menjawab tantangan ini dibutuhkan: Sosialisasi masif dan berkelanjutan Penguatan SDM auditor halal Kolaborasi lintas sektor yang lebih baik Reformasi birokrasi pelayanan halal (termasuk digitalisasi) | P24: Netral | Q24: Komunikasi dan sumber daya adalah dua faktor paling penting dalam implementasi JPH di Indonesia. Tanpa keduanya, kebijakan ini sulit dipahami dan dilaksanakan secara efektif. Namun, disposisi dan struktur birokrasi tetap diperlukan sebagai penguat sistem secara keseluruhan. | R24: iya | S24: 1 tahun | T24: jawab barat | U24: F&B | V24: SMA
A25: Siti Asyri Masnawiyah | B25: Mahasiswa | C25: Sama penting (1) | D25: Sama penting (1) | E25: Sama penting (1) | F25: Sama penting (1) | G25: Sama penting (1) | H25: Sama penting (1) | I25: Perempuan | K25: Sukabumi | L25: Sangat Penting | M25: Sangat Penting | N25: Sangat Penting | O25: Tantangan terbesar dalam implementasi Jaminan Produk Halal (JPH) di Indonesia mencakup kurangnya sosialisasi yang efektif kepada pelaku usaha, terutama UMKM, sehingga banyak yang belum memahami kewajiban sertifikasi halal. Selain itu, keterbatasan sumber daya manusia seperti auditor halal memperlambat proses sertifikasi. Dari sisi disposisi, masih terdapat resistensi dari pelaku usaha karena menganggap prosesnya rumit dan mahal. Struktur birokrasi yang berbelit dan lambat juga menjadi hambatan dalam mewujudkan layanan JPH yang efisien dan merata. | P25: Sangat Penting | Q25: Ya, dalam konteks implementasi JPH di Indonesia, faktor komunikasi dan sumber daya manusia bisa dianggap lebih penting dibandingkan yang lain. Komunikasi yang efektif sangat krusial karena banyak pelaku usaha, khususnya UMKM, belum memahami pentingnya sertifikasi halal dan prosedurnya. Tanpa pemahaman yang memadai, kepatuhan akan rendah. Selain itu, ketersediaan sumber daya manusia seperti auditor halal dan penyuluh sangat menentukan kelancaran proses sertifikasi. Tanpa SDM yang cukup dan kompeten, proses akan lambat meskipun sistem dan regulasi sudah ada. Faktor-faktor ini menjadi fondasi bagi keberhasilan implementasi JPH secara menyeluruh. | R25: Ya, salah satu faktor penting yang juga memengaruhi keberhasilan implementasi JPH namun tidak tercakup dalam kriteria di atas adalah dukungan politik dan regulasi yang konsisten. Kebijakan pemerintah yang kuat, harmonisasi regulasi antarinstansi, serta komitmen politik dari pusat hingga daerah sangat menentukan arah dan keberlanjutan program JPH. Selain itu, partisipasi aktif masyarakat dan lembaga keagamaan juga berperan besar dalam membangun kesadaran dan kepercayaan terhadap pentingnya produk halal. Tanpa dukungan ini, implementasi JPH berisiko stagnan meskipun faktor teknis lainnya terpenuhi. | S25: 1-6 bulan | T25: Jawa Barat | U25: Basreng renyah | V25: SMA
A26: Muhamad fiqri | B26: Mahasiswa | C26: Komunikasi sangat jauh lebih penting (9) | D26: Komunikasi lebih penting (7) | E26: Komunikasi agak lebih penting (5) | F26: Sama penting (1) | G26: Sumber Daya sedikit lebih penting (3) | H26: Struktur Birokrasi sedikit lebih penting (1/3) | I26: Laki-laki | K26: Sukabumi | L26: Netral | M26: Tidak Penting | N26: Tidak Penting | O26: Kurangnya literasi dari masyarakat | P26: Sangat Penting | Q26: Ada .. | R26: Tidak ada | S26: 1-6 bulan | T26: Jawa barat | U26: Kantin sehat | V26: SMA
A27: Elsa Elyanti Suherman | B27: Mahasiswa | C27: Sumber Daya sangat jauh lebih penting (1/9) | D27: Komunikasi sangat jauh lebih penting (9) | E27: Sama penting (1) | F27: Sumber Daya lebih penting (7) | G27: Struktur Birokrasi lebih penting (1/7) | H27: Sama penting (1) | I27: Perempuan | K27: Kota Sukabumi | L27: Sangat Penting | M27: Sangat Penting | N27: Sangat Penting | O27: Tantangan utama implementasi JPH di Indonesia meliputi komunikasi yang kurang merata, terbatasnya auditor dan fasilitas halal, rendahnya komitmen pelaksana, serta birokrasi yang rumit dan lamban. | P27: Sangat Penting | Q27: Ya, faktor sumber daya merupakan yang paling krusial dalam implementasi JPH di Indonesia. Tanpa auditor halal yang memadai dan fasilitas pendukung seperti laboratorium yang tersebar merata, proses sertifikasi menjadi lambat dan tidak merata. Meskipun komunikasi dan struktur birokrasi penting, kekurangan sumber daya langsung menghambat pelaksanaan teknis di lapangan, terutama di daerah terpencil dan bagi pelaku UMKM. | R27: Ya, salah satu faktor penting yang juga memengaruhi keberhasilan implementasi JPH namun sering luput dari perhatian adalah kesadaran dan partisipasi masyarakat. Tanpa adanya permintaan dan dorongan dari konsumen terhadap produk halal, pelaku usaha akan kurang terdorong untuk mengurus sertifikasi. Kesadaran konsumen tentang pentingnya produk halal dapat menjadi pendorong kuat agar seluruh ekosistem JPH berjalan efektif, terutama dalam mendorong pelaku usaha untuk patuh terhadap regulasi. | S27: 1 tahun | T27: Jawa Barat | U27: Seblak | V27: S1
A28: Mutia Rahmah | B28: Mahasiswa | C28: Sama penting (1) | D28: Sama penting (1) | E28: Sama penting (1) | F28: Sama penting (1) | G28: Sama penting (1) | H28: Sama penting (1) | I28: Perempuan | K28: Sukabumi | L28: Sangat Penting | M28: Sangat Penting | N28: Sangat Penting | O28: Tantangan terbesar dalam implementasi Jaminan Produk Halal (JPH) di Indonesia berpusat pada kurangnya komunikasi yang efektif, keterbatasan sumber daya seperti auditor dan anggaran, serta disposisi negatif dari pelaku usaha yang menganggap prosesnya rumit dan mahal. Selain itu, struktur birokrasi yang kompleks dan koordinasi yang lambat antar lembaga juga menjadi hambatan. | P28: Sangat Penting | Q28: Dari semua faktor ini, disposisi dan kemauan dari seluruh pemangku kepentingan adalah yang paling krusial, karena tanpa kesadaran dan komitmen, tantangan lain sulit diatasi. | R28: Faktor lain yang tak kalah penting adalah pemanfaatan teknologi digital untuk mempercepat proses dan meningkatkan transparansi, yang pada akhirnya akan memudahkan semua pihak terlibat. | S28: 1-6 bulan | T28: Jawa Barat | U28: Makanan | V28: SMA
A29: Triana Permata Rizki | B29: Mahasiswa | C29: Sama penting (1) | D29: Sama penting (1) | E29: Sama penting (1) | F29: Sama penting (1) | G29: Sama penting (1) | H29: Sama penting (1) | I29: Perempuan | K29: Kabupaten sukabumi | L29: Sangat Penting | M29: Sangat Penting | N29: Sangat Penting | P29: Sangat Penting | S29: 1 tahun | T29: Jawa barat | U29: Jualan risol | V29: SMA
A30: Ihsan Nurjaman | B30: Mahasiswa | C30: Komunikasi sangat jauh lebih penting (9) | D30: Komunikasi sangat jauh lebih penting (9) | E30: Komunikasi sangat jauh lebih penting (9) | F30: Sumber Daya sangat jauh lebih penting (9) | G30: Sumber Daya sangat jauh lebih penting (9) | H30: Disposisi sangat jauh lebih penting (9) | I30: Laki-laki | K30: Kab sukabumi | L30: Sangat Penting | M30: Sangat Penting | N30: Sangat Penting | O30: Komunikasi: Kurangnya sosialisasi dan pemahaman publik serta pelaku usaha tentang kewajiban sertifikasi halal. | P30: Sangat Penting | Q30: Ya, faktor sumber daya dapat dianggap paling krusial dalam implementasi JPH di Indonesia. Tanpa jumlah auditor halal, LPH, dan tenaga ahli yang memadai, proses sertifikasi akan terhambat, meskipun komunikasi dan struktur birokrasi sudah baik. | R30: Iyaa berul | S30: 1-6 bulan | T30: Jawa barat | U30: Bidng jasa Photography | V30: S1
A31: Saiful Hidayatullah | B31: Mahasiswa | C31: Sama penting (1) | D31: Komunikasi agak lebih penting (5) | E31: Sama penting (1) | F31: Disposisi sedikit lebih penting (1/3) | G31: Struktur Birokrasi sedikit lebih penting (1/3) | H31: Sama penting (1) | I31: Laki-laki | K31: Kab. Sukabumi | L31: Penting | M31: Sangat Penting | N31: Netral | O31: Kurangnya komunikasi antar pemerintah dan pelaku usaha | P31: Penting | Q31: Tidak, karena ya esensi dalam hal tersebut bisa dilihat dari sudut pandang produk | R31: Mungkin sistem pengaturan sumber daya nya dan struktur briokrasi nya harus diperhatikan | S31: 1,5 -2 tahun | T31: Jawa Barat | U31: Makanan | V31: SMA
A32: Karenina julilian zalfa | B32: Mahasiswa | C32: Sama penting (1) | D32: Sama penting (1) | E32: Sama penting (1) | F32: Sumber Daya agak lebih penting (5) | G32: Sama penting (1) | H32: Sama penting (1) | I32: Perempuan | K32: Bekasi | L32: Penting | M32: Netral | N32: Penting | O32: Tantangan terbesar ada pada gap antara kebijakan yang sudah bagus di atas kertas dan kemampuan eksekusinya di lapangan. Perlu komunikasi yang seragam, sumber daya yang memadai, komitmen kuat dari pelaksana, dan struktur birokrasi yang sederhana agar implementasi JPH berjalan efektif. | P32: Penting | Q32: Dalam kondisi Indonesia sekarang, komunikasi adalah pintu masuk agar pelaku usaha mau bergerak, dan sumber daya adalah mesin penggerak agar kebijakan JPH bisa dieksekusi. Tanpa keduanya, disposisi dan pembenahan birokrasi pun akan berjalan tersendat. | R32: Empat faktor awal (komunikasi, sumber daya, disposisi, birokrasi) memang inti, tapi budaya/persepsi, tekanan pasar, dukungan politik, dan kesiapan teknologi juga sangat menentukan apakah JPH hanya berhenti sebagai kebijakan atau benar-benar berjalan di lapangan. | S32: 1-6 bulan | T32: Jawa Barat | U32: Cake | V32: SMA
A33: Dedd Hidayatullah | B33: Mahasiswa | C33: Sama penting (1) | D33: Disposisi lebih penting (1/7) | E33: Struktur Birokrasiagak lebih penting (1/5) | F33: Disposisi agak lebih penting (1/5) | G33: Sama penting (1) | H33: Sama penting (1) | I33: Laki-laki | K33: Sukabumi | L33: Sangat Penting | M33: Sangat Penting | N33: Sangat Penting | O33: tantangan terbesar dalam implementasi JPH di Indonesia adalah menciptakan sistem yang terintegrasi, efisien, dan transparan yang didukung oleh komunikasi yang baik dan sumber daya yang memadai. Mengatasi tantangan-tantangan ini membutuhkan kolaborasi yang kuat antara pemerintah, ulama, pelaku usaha, dan masyarakat. | P33: Sangat Penting | Q33: Struktur birokrasi dan sumber daya merupakan faktor terpenting dalam implementasi JPH di Indonesia. Birokrasi yang berbelit-belit menjadi fondasi masalah karena menghambat semua proses, termasuk komunikasi dan efisiensi. | R33: Berdasarkan kriteria yang telah dibahas (komunikasi, sumber daya, disposisi, dan struktur birokrasi), ada faktor lain yang tak kalah penting dalam keberhasilan implementasi JPH, yaitu kesadaran dan komitmen pelaku usaha. | S33: 1-6 bulan | T33: Jawa barat | U33: Ayam kampung | V33: SMA
A34: nurisa arsya | B34: mahasiswa | C34: Sama penting (1) | D34: Komunikasi sangat jauh lebih penting (9) | E34: Struktur Birokrasiagak lebih penting (1/5) | F34: Sumber Daya lebih penting (7) | G34: Sumber Daya sangat jauh lebih penting (9) | H34: Disposisi agak lebih penting (5) | I34: Perempuan | K34: Sukabumi | L34: Netral | M34: Netral | N34: Netral | O34: belum testruktur | P34: Netral | Q34: iyaaaa | R34: belim Ada | S34: 1 tahun | T34: Jawa barat | U34: - | V34: SMA
A35: Siti Purnama Aula | B35: Mahasiswa | C35: Sama penting (1) | D35: Komunikasi lebih penting (7) | E35: Struktur Birokrasilebih penting (1/7) | F35: Sumber Daya lebih penting (7) | G35: Sama penting (1) | H35: Struktur Birokrasi lebih penting (1/7) | I35: Perempuan | K35: Sukabumi | L35: Sangat Penting | M35: Sangat Penting | N35: Sangat Penting | O35: Tantangan terbesar dalam implementasi Jaminan Produk Halal (JPH) di Indonesia, terkait komunikasi, sumber daya, disposisi, dan struktur birokrasi, meliputi kesenjangan pemahaman, keterbatasan sumber daya manusia dan anggaran, tumpang tindih kewenangan, serta kompleksitas birokrasi. | P35: Sangat Penting | Q35: Ya, dalam konteks implementasi Jaminan Produk Halal (JPH) di Indonesia, beberapa faktor memang dirasa lebih krusial daripada yang lain. Pemahaman dan kesadaran masyarakat serta pelaku usaha mengenai pentingnya JPH merupakan faktor kunci. Tanpa pemahaman yang baik, implementasi JPH akan sulit berjalan efektif. Selain itu, keberadaan infrastruktur dan sistem yang mendukung, seperti lembaga sertifikasi halal yang kredibel dan terpercaya (BPJPH), juga sangat penting. Tanpa infrastruktur yang memadai, proses sertifikasi akan terhambat dan kepercayaan masyarakat terhadap produk halal bisa berkurang. | R35: Selain kriteria yang sudah disebutkan, beberapa faktor lain yang dapat mempengaruhi keberhasilan implementasi Jaminan Produk Halal (JPH) adalah tingkat kesadaran dan pemahaman masyarakat tentang halal, dukungan regulasi yang kuat dan implementasinya di lapangan, serta kemampuan pelaku usaha dalam menjaga kualitas dan konsistensi kehalalan produk secara berkelanjutan. | S35: 1 tahun | T35: Jawa Barat | U35: Fashion | V35: SMA
A36: Chandra rosaady pasya | B36: Owner | C36: Komunikasi sangat jauh lebih penting (9) | D36: Komunikasi sangat jauh lebih penting (9) | E36: Komunikasi sangat jauh lebih penting (9) | F36: Sumber Daya sangat jauh lebih penting (9) | G36: Sumber Daya sangat jauh lebih penting (9) | H36: Sama penting (1) | I36: Laki-laki | K36: Bandung | L36: Sangat Penting | M36: Sangat Penting | N36: Sangat Penting | O36: Tantangannya adalah dukungan dari perusahaan besar sebagai supplier UMKM untuk turut mendukung JPH karena banyak perusahaan supplier tidak kooperatif dalam hal pengurusan JPH | P36: Tidak Penting | Q36: Dukungan sumberdaya dan pemasaran sangat kurang | R36: Tidak ada | S36: 1-6 bulan | T36: Jawa barat | U36: Pakaian anak | V36: S1
A37: Maryam Aulia | B37: Mahasiswa | C37: Komunikasi sangat jauh lebih penting (9) | D37: Disposisi sangat jauh lebih penting (1/9) | E37: Komunikasi sangat jauh lebih penting (9) | F37: Disposisi sangat jauh lebih penting (1/9) | G37: Sumber Daya sangat jauh lebih penting (9) | H37: Disposisi sangat jauh lebih penting (9) | I37: Perempuan | K37: Sukabumi | L37: Sangat Tidak Penting | M37: Sangat Penting | N37: Sangat Penting | O37: Penerapan JPH itu kayak bikin konten viral: nggak cukup cuma punya modal kamera (sumber daya), harus ada tim kreatif (disposisi), proses upload yang lancar (komunikasi), dan platform yang gak crash (birokrasi). Kalau salah satu goyang, hasilnya bisa gak trending sama sekali | P37: Sangat Penting | Q37: Komunikasi 🔥 Sangat tinggi Jadi fondasi awal agar semua stakeholder paham & tergerak. Disposisi 🔥 Tinggi Tanpa kemauan dari pelaku usaha, semua regulasi hanya jadi dokumen. Birokrasi ⚠️ Tinggi tapi teknis Harus efisien, biar gak bikin pelaku usaha kabur. Sumber Daya ⚠️ Menengah Bisa dibantu atau diusahakan jika 3 faktor lain sudah kuat. | R37: Sertifikasi halal itu bukan cuma soal regulasi, tapi juga soal mindset, akses, dan motivasi." Tanpa menyentuh sisi sosial-budaya dan ekonomi, JPH bakal jadi regulasi yang jalan sendiri tanpa pengikut. | S37: 1,5 -2 tahun | T37: Jawa Barat | U37: Perbankan | V37: SMA
A38: Adnan laudza prasetya | B38: Mahasiswa | C38: Komunikasi sangat jauh lebih penting (9) | D38: Komunikasi sangat jauh lebih penting (9) | E38: Komunikasi sangat jauh lebih penting (9) | F38: Sumber Daya sangat jauh lebih penting (9) | G38: Sumber Daya sangat jauh lebih penting (9) | H38: Disposisi sangat jauh lebih penting (9) | I38: Laki-laki | K38: Kabupaten sukabumi | L38: Sangat Penting | M38: Sangat Penting | N38: Netral | P38: Netral | S38: 1-6 bulan | T38: Jawa barat | U38: Toko sembako | V38: SMA
A39: Silvi Putri Rahayu | B39: Mahasiswa Ekonomi Syariah | C39: Sama penting (1) | D39: Komunikasi lebih penting (7) | E39: Komunikasi lebih penting (7) | F39: Sumber Daya agak lebih penting (5) | G39: Sumber Daya lebih penting (7) | H39: Disposisi sedikit lebih penting (3) | I39: Perempuan | K39: Sukabumi | L39: Sangat Penting | M39: Sangat Penting | N39: Penting | O39: Tantangan terbesar dalam implementasi JPH di Indonesia adalah keterbatasan sumber daya dan struktur birokrasi yang kompleks. | P39: Penting | Q39: Ya, komitmen dan ketersediaan sumber daya adalah faktor yang paling penting dalam implementasi JPH di Indonesia karena keduanya dapat mempengaruhi keberhasilan implementasi secara signifikan. | R39: Ya, faktor lain yang mempengaruhi keberhasilan implementasi JPH adalah partisipasi aktif masyarakat dan teknologi informasi yang memadai. Partisipasi masyarakat dapat meningkatkan kesadaran dan kepatuhan, sedangkan teknologi informasi dapat memfasilitasi monitoring dan evaluasi implementasi JPH. | S39: 1-6 bulan | T39: Jawa barat | U39: Mahasiswa | V39: S1
A40: Nurul Kamila | B40: Mahasiswa Ekonomi Syariah | C40: Sama penting (1) | D40: Sama penting (1) | E40: Sama penting (1) | F40: Sumber Daya sedikit lebih penting (3) | G40: Sumber Daya sedikit lebih penting (3) | H40: Sama penting (1) | I40: Perempuan | K40: Sukabumi | L40: Netral | M40: Penting | N40: Penting | O40: Kurangnya sosialisasi yang merata, keterbatasan auditor dan laboratorium halal, birokrasi yang berbelit, serta belum semua pelaksana memiliki komitmen kuat. | P40: Penting | Q40: Komunikasi dan sumber daya. Tanpa pemahaman dan dukungan SDM/infrastruktur, implementasi tidak berjalan optimal meski ada regulasi. | R40: Biaya sertifikasi bagi UMKM, dukungan politik, dan pengaruh budaya lokal terhadap pemahaman halal. | S40: 1-6 bulan | T40: Jawa Barat | U40: Mahasiswa | V40: S1
...

Sheet Data Asli
A1: No. | B1: Timestamp | C1: Nama | D1: Nama | E1: Jabatan | F1: Komunikasi vs Sumber Daya | G1: Komunikasi vs Disposisi | H1: Komunikasi vs Struktur Birokrasi | I1: Sumber Daya vs Disposisi | J1: Sumber Daya vs Struktur Birokrasi | K1: Disposisi vs Struktur Birokrasi | L1: Jenis Kelamin | M1: No. Telephon/Whatsapp* | N1: Asal Kota/Kabupaten | O1: Sejauh mana komunikasi yang efektif antara pemerintah, industri, dan masyarakat mempengaruhi keberhasilan implementasi JPH di Indonesia? | P1: Sejauh mana ketersediaan sumber daya, seperti dana dan tenaga ahli, mempengaruhi implementasi JPH? | Q1: Sejauh mana disposisi atau komitmen dari para pemangku kepentingan (pemerintah dan industri) mempengaruhi implementasi JPH? | R1: Apa tantangan terbesar yang Anda hadapi dalam implementasi JPH di Indonesia terkait dengan komunikasi, sumber daya, disposisi, dan struktur birokrasi? | S1: Sejauh mana struktur birokrasi yang efisien dan jelas mendukung implementasi JPH? | T1: Apakah Anda merasa bahwa faktor-faktor tertentu lebih penting daripada yang lain dalam konteks implementasi JPH di Indonesia? Jika ya, jelaskan mengapa. | U1: Apakah ada faktor lain yang menurut Anda juga mempengaruhi keberhasilan implementasi JPH, namun tidak tercakup dalam kriteria di atas? | V1: Lama Pengalaman dalam Implementasi JPH | W1: Alamat e-mail | X1: Provinsi | Y1: Jenis Produk Industri/UMKM (Jika dari Pelaku Usaha) | Z1: Pendidikan Terakhir | AA1: Penilaian Kriteria Berpasangan
A2: 1 | B2: 45780.896 | C2: Sugeng ribowo | D2: Perbankan | E2: Kepala | F2: Sama penting (1) | G2: Sama penting (1) | H2: Komunikasi lebih penting (7) | I2: Sumber Daya lebih penting (7) | J2: Sumber Daya lebih penting (7) | K2: Sama penting (1)
A3: 2 | B3: 45794.538 | D3: UMKM | E3: Pelaku usaha | F3: Komunikasi sangat jauh lebih penting (9) | G3: Komunikasi sangat jauh lebih penting (9) | H3: Komunikasi sangat jauh lebih penting (9) | I3: Sumber Daya sangat jauh lebih penting (9) | J3: Sumber Daya lebih penting (7) | K3: Disposisi sedikit lebih penting (3) | L3: Laki-laki | N3: Bogor | O3: Netral | P3: Sangat Tidak Penting | Q3: Tidak Penting | S3: Netral | V3: 0-5 tahun
A4: 3 | B4: 45873.904 | D4: Indiah | E4: Pembina Industri | F4: Komunikasi lebih penting (7) | G4: Sama penting (1) | H4: Komunikasi sedikit lebih penting (3) | I4: Sama penting (1) | J4: Struktur Birokrasi sedikit lebih penting (1/3) | K4: Sama penting (1) | L4: Perempuan | N4: Yogyakarta | O4: Sangat Penting | P4: Penting | Q4: Penting | R4: Komunikasi | S4: Sangat Penting | T4: Komunikasi agar seluruh lapisan memahami regulasi tersebut. | U4: Suara konsumen terkait kebutuhan Halal | V4: 1,5 -2 tahun | W4: indiah.dardanela@gmail.com | X4: DI Yogyakarta | Y4: - | Z4: S2
A5: 4 | B5: 45873.912 | D5: Alim Mahawan Nuryadi | E5: Pembina Industri | F5: Komunikasi agak lebih penting (5) | G5: Komunikasi lebih penting (7) | H5: Komunikasi lebih penting (7) | I5: Sumber Daya lebih penting (7) | J5: Sumber Daya sangat jauh lebih penting (9) | K5: Disposisi lebih penting (7) | L5: Laki-laki | N5: Manado | O5: Sangat Penting | P5: Sangat Penting | Q5: Sangat Penting | R5: Disposisi pemangku kepentingan dapat merubah ego sektoral dari berbagai pihak yang memiliki kepentingan yang berbeda. | S5: Sangat Penting | T5: Faktor Disposisi menjadikan kepentingan yg berbeda disetiap elemen masyarakat | V5: > 3 tahun | W5: alimmahawan@gmail.com | X5: Sulawesi Utara | Y5: Bukan PU | Z5: S2
A6: 5 | B6: 45873.967 | D6: Fitriana Djafar | E6: AMMI Ahli Madya/ Auditor Halal | F6: Sumber Daya sangat jauh lebih penting (1/9) | G6: Disposisi sangat jauh lebih penting (1/9) | H6: Struktur Birokrasi sangat jauh lebih penting (1/9) | I6: Sumber Daya sangat jauh lebih penting (9) | J6: Sumber Daya sangat jauh lebih penting (9) | K6: Disposisi sangat jauh lebih penting (9) | L6: Perempuan | N6: Kota Banda Aceh | O6: Penting | P6: Sangat Penting | Q6: Sangat Penting | R6: Sumber daya adalah tantangan terbesar dalam implementasi JPH di Indonesia karena faktor ini merupakan pondasi teknis dan operasional dari implementasi JPH. Tanpa sumber daya (tenaga ahli, dana, fasilitas, dan teknologi), kebijakan tidak bisa dijalankan meskipun komunikasi baik dan birokrasi mendukung. | S6: Sangat Penting | T6: Ke empat faktor tersebut saling terkait satu dan lainnya, namun dalam konteks implementasi bilamana dilakukan urutan berdasarkan prioritas faktor yang lebih penting yaitu sebagai berikut: 1).sumber daya; 2) disposisi, 3)struktur birokrasi dan 4) komunikasi | U6: Ya, terdapat faktor lainnya yang juga signifikan mempengaruhi implementasi JPH, antara lain : 1) Budaya, Kesadaran dan Persepsi Masyarakat (terutama konsumen dan Pelaku Usaha); 2) Peraturan Turunan (spt: PP, Permen, dan SOP teknis) yang jelas dan konsisten) serta skema dan standar audit halal yang jelas dan terinci; 3) Dukungan Teknologi/Sistem Digital yang responsif dan akuntable/aplikasi tidak lambat/tidak sering eror/; 4) Peran pihak swasta/ industri dan atau pihak Fasilitator dalam hal edukasi halal, pembiayaan sertifikasi halal dan pendampingan UMKM; dan 5) Faktor ekonomi dan beban biaya sertifikasi halal (UMKM terbebani biaya terutama jika tidak ada subsidi/ diskon/ program fasilitasi). | V6: 2,5 -3 tahun | W6: fitrianadjafar79@gmail.com | X6: Aceh | Y6: *Bukan Pelaku Usaha | Z6: S2
A7: 6 | B7: 45874.384 | D7: Muhammad Reza | E7: Direktur | F7: Komunikasi sangat jauh lebih penting (9) | G7: Komunikasi sangat jauh lebih penting (9) | H7: Komunikasi sangat jauh lebih penting (9) | I7: Sumber Daya sangat jauh lebih penting (9) | J7: Sumber Daya sangat jauh lebih penting (9) | K7: Struktur Birokrasi sangat jauh lebih penting (1/9) | L7: Laki-laki | N7: Bulukumba | O7: Sangat Penting | P7: Sangat Penting | Q7: Sangat Penting | R7: Tidak ada | S7: Sangat Penting | T7: Tidak ada | U7: Tidak ada | V7: 1 tahun | W7: rezarhasya19@gmail.com | X7: Sulawesi Selatan | Y7: Air Minum Kemasan | Z7: SMA
A8: 7 | B8: 45874.387 | D8: Yudo Purnomo | E8: PMB Madya | F8: Sama penting (1) | G8: Komunikasi lebih penting (7) | H8: Komunikasi lebih penting (7) | I8: Sumber Daya lebih penting (7) | J8: Sumber Daya lebih penting (7) | K8: Struktur Birokrasi lebih penting (1/7) | L8: Laki-laki | N8: Padang | O8: Sangat Penting | P8: Penting | Q8: Netral | R8: Diperlukan peran aktif pemerintah dan stakeholder terkait untuk lebih menyebarkan pentingnya sertifikasi kehalalan produk | S8: Penting | T8: Iya, terutama komunikasi dan SDM. Dikarenakan komunikasi yg baik akan mempercepat tersebarnya informasi tentang SH. Dan SDM yang baik juga akan lebih mengakselerasi penyebaran informasi | U8: Terkait partisipasi masyarakat. Masih kurangnya partisipasi aktif masyarakar dalam melakukan SH produknya | V8: 2,5 -3 tahun | W8: yudopurnomo85@gmail.com | X8: Sumatera Barat | Y8: Layanan jasa industri | Z8: S2
A9: 8 | B9: 45874.39 | D9: Novreza Utama Putra | E9: Pembina Industri | F9: Komunikasi sedikit lebih penting (3) | G9: Komunikasi agak lebih penting (5) | H9: Sama penting (1) | I9: Sama penting (1) | J9: Sumber Daya sedikit lebih penting (3) | K9: Disposisi sedikit lebih penting (3) | L9: Laki-laki | N9: Bekasi | O9: Netral | P9: Penting | Q9: Penting | R9: Penyebaran informasi tentang JPH terhadap masyarakat masih sangat minim tersampaikan, perlu adanya strategi jitu dalam memberikan edukasi kepada masyarakat. | S9: Penting | T9: Tidak | U9: Tingkat keyakinan spritual masing-masing individu tentang halal. | V9: > 3 tahun | W9: novreza2015@gmail.com | X9: Jawa Barat | Y9: Government | Z9: S2
A10: 9 | B10: 45874.409 | D10: Muhammad Alvian Caesar | E10: Pelajar | F10: Komunikasi sangat jauh lebih penting (9) | G10: Komunikasi sangat jauh lebih penting (9) | H10: Komunikasi sedikit lebih penting (3) | I10: Sumber Daya sangat jauh lebih penting (9) | J10: Sumber Daya lebih penting (7) | K10: Disposisi sangat jauh lebih penting (9) | L10: Laki-laki | N10: Kab Demak | O10: Penting | P10: Penting | Q10: Penting | R10: Komunikassi,Sumber daya,Disposisi, strukrur birokrasi | S10: Penting | T10: Ya, dalam konteks implementasi Jaminan Produk Halal (JPH) di Indonesia, faktor sumber daya dapat dikatakan lebih penting daripada faktor lainnya — meskipun semua faktor saling berkaitan. Berikut penjelasan mengapa sumber daya menjadi faktor paling krusial: Sumber daya merupakan fondasi dari semua faktor lainnya. Tanpa SDM yang kompeten, auditor yang cukup, penyelia yang terlatih, dan dukungan fasilitas, maka komunikasi, niat baik, dan perbaikan birokrasi tidak akan cukup mendorong suksesnya implementasi JPH. Namun demikian, keberhasilan implementasi JPH tetap membutuhkan sinergi antar seluruh faktor, bukan berdiri sendiri. | U10: Faktor-faktor di luar komunikasi, sumber daya, disposisi, dan struktur birokrasi yang juga sangat memengaruhi keberhasilan JPH adalah: 1. Kesadaran masyarakat 2. Penegakan hukum dan regulasi 3. Teknologi dan infrastruktur 4. Peran pendamping/ormas 5. Transparansi bahan baku > Semua faktor tersebut berperan sebagai pendukung sistemik yang jika diabaikan, akan menghambat implementasi JPH meskipun struktur formalnya sudah dibangun. | V10: 2,5 -3 tahun | W10: alviancesar@gmail.com | X10: Jawa Tengah | Y10: Peyek Mbok Marti | Z10: SMA
A11: 10 | B11: 45874.432 | D11: Pujianto | E11: Pemilik | F11: Sumber Daya sangat jauh lebih penting (1/9) | G11: Komunikasi sangat jauh lebih penting (9) | H11: Komunikasi sangat jauh lebih penting (9) | I11: Sumber Daya sangat jauh lebih penting (9) | J11: Sumber Daya sangat jauh lebih penting (9) | K11: Disposisi sangat jauh lebih penting (9) | L11: Laki-laki | N11: Kabupaten Semarang | O11: Sangat Penting | P11: Sangat Penting | Q11: Sangat Penting | R11: Ada beberapa hal ya g kami hadapi yaitu kurangnya koordinasi dan transparansi dalam penyampaian informasi termasuk dalam perizinan dan pengawasan serta keterbatasan SDM dan anggaran serta sistem yang tidak terintegrasi | S11: Sangat Penting | T11: Tidak...semua faktor diatas sudah mencakup dalam pendukung implementasi JPH tersebut | U11: Mungkin sering diadakan bimbingan teknis ke lokasi agar mudah dipahami | V11: 1 tahun | W11: satria.piningit3083@gmail.com | X11: Jawa Tengah | Y11: Keripik | Z11: S1
A12: 11 | B12: 45874.46 | D12: Siti khotimah | E12: Pimpinan | F12: Sama penting (1) | G12: Sama penting (1) | H12: Sama penting (1) | I12: Sama penting (1) | J12: Sama penting (1) | K12: Sama penting (1) | L12: Perempuan | N12: Demak | O12: Sangat Penting | P12: Sangat Penting | Q12: Sangat Penting | S12: Sangat Penting | T12: ya | U12: tidak ada | V12: 1-6 bulan | W12: khotimah.siti2205@gmail.com | X12: Jawa tengah | Y12: Sambel pecel kenangajaya | Z12: S1
A13: 12 | B13: 45874.479 | D13: Faisal Muin | E13: Direktur | F13: Komunikasi lebih penting (7) | G13: Komunikasi lebih penting (7) | H13: Komunikasi lebih penting (7) | I13: Sama penting (1) | J13: Sama penting (1) | K13: Sama penting (1) | L13: Laki-laki | N13: Pangkajene dan kepulauan | O13: Sangat Penting | P13: Sangat Penting | Q13: Sangat Penting | R13: Meniyapkan atau mencari bahan baku yang sesuai dengan peraturan. | S13: Sangat Penting | T13: Ya, agar konsumen lebih percaya atau yakin dengan produk yang kami tawarkan. | U13: Tidak ada, karena semua sudah dielaskan dengan sangat jelas. | V13: 2,5 -3 tahun | W13: amdkhafas@gmail.com | X13: Sulawesi Selatan | Y13: Amdk | Z13: SMA
A14: 13 | B14: 45874.522 | D14: RITA ZULIANAWATI | E14: PEMILIK | F14: Sama penting (1) | G14: Sama penting (1) | H14: Sama penting (1) | I14: Sama penting (1) | J14: Sama penting (1) | K14: Sama penting (1) | L14: Perempuan | N14: DEMAK | O14: Sangat Penting | P14: Sangat Penting | Q14: Sangat Penting | R14: Biaya, pemahaman dan kompleksitas regulasi | S14: Sangat Penting | T14: Ya,karena komitmen dan tanggungjawab manajemen merupakan faktor terpenting disuatu lini perusahaan dan kebijakan halal harus diimplementasikan secara konsisten | U14: Ada..yaitu pemahaman dan kesadaran karyawan serta ketersediaan sumber daya serta dukungan eksternal | V14: 1 tahun | W14: anaryta234@gmail.com | X14: JAWA TENGAH | Y14: MAKANAN RINGAN SIAP SANTAP | Z14: S1
A15: 14 | B15: 45874.532 | D15: zainal Arifin | E15: Wirasawasta | F15: Komunikasi lebih penting (7) | G15: Sama penting (1) | H15: Struktur Birokrasisedikit lebih penting (1/3) | I15: Disposisi sedikit lebih penting (1/3) | J15: Struktur Birokrasi sedikit lebih penting (1/3) | K15: Struktur Birokrasi sedikit lebih penting (1/3) | L15: Laki-laki | N15: Pinrang | O15: Netral | P15: Tidak Penting | Q15: Tidak Penting | S15: Netral | V15: 1-6 bulan | W15: Lerang lerang . | X15: Sulawesi selatan | Y15: Bakso ayam , Bakso sapi . | Z15: SMA
A16: 15 | B16: 45874.555 | D16: HERMAN | E16: DIREKTUR | F16: Sama penting (1) | G16: Komunikasi lebih penting (7) | H16: Sama penting (1) | I16: Sumber Daya lebih penting (7) | J16: Sama penting (1) | K16: Sama penting (1) | L16: Laki-laki | N16: SINJAI | O16: Penting | P16: Penting | Q16: Penting | R16: Kurang informasi | S16: Penting | T16: Tidak | U16: Tidak | V16: 1-6 bulan | W16: cv.hikmahlestari01@gmail.com | X16: SULAWESI SELATAN | Y16: AMDK CUP | Z16: SMP
A17: 16 | B17: 45874.588 | D17: Sugira | E17: Pemilik | F17: Sama penting (1) | G17: Komunikasi lebih penting (7) | H17: Komunikasi sangat jauh lebih penting (9) | I17: Sumber Daya agak lebih penting (5) | J17: Sumber Daya sedikit lebih penting (3) | K17: Sama penting (1) | L17: Perempuan | N17: BONE | O17: Sangat Penting | P17: Sangat Penting | Q17: Penting | R17: Dana | S17: Sangat Penting | T17: Tidak | U17: Sudah tercakup semua | V17: > 3 tahun | W17: sugira.ira77@gmail.com | X17: Sulawesi Selatan | Y17: ABON IKAN dan Abon Ayam | Z17: S1
A18: 17 | B18: 45874.618 | D18: Novia Arizandy | E18: Pemilik Usaha | F18: Sama penting (1) | G18: Sama penting (1) | H18: Sama penting (1) | I18: Sama penting (1) | J18: Sama penting (1) | K18: Sama penting (1) | L18: Perempuan | N18: Watampone / Bone | O18: Sangat Penting | P18: Sangat Penting | Q18: Sangat Penting | R18: - | S18: Sangat Penting | T18: - | U18: - | V18: 1-6 bulan | W18: novifaisal99@gmail.com | X18: Sulawesi Selatan | Y18: Abon | Z18: SMA
A19: 18 | B19: 45874.628 | D19: Fajri Haykal Ramadhan | E19: Karyawan swasta | F19: Sama penting (1) | G19: Komunikasi lebih penting (7) | H19: Struktur Birokrasisedikit lebih penting (1/3) | I19: Sumber Daya sangat jauh lebih penting (9) | J19: Sumber Daya sangat jauh lebih penting (9) | K19: Struktur Birokrasi sedikit lebih penting (1/3) | L19: Laki-laki | N19: Cianjur | O19: Penting | P19: Sangat Penting | Q19: Penting | R19: Sumber daya karena masyarakar belum memahami produk halal | S19: Penting | T19: Ya, inovasi dalam pengelolaan JOH sehingga produk lebih unggul | U19: Keterbukaan dan jg pengelolaan keuangan | V19: > 3 tahun | W19: fajrihaykal99@gmail.com | X19: Jawa barat | Y19: Makanan | Z19: S2
A20: 19 | B20: 45874.797 | D20: Nadhia | E20: IRT | F20: Komunikasi lebih penting (7) | G20: Disposisi lebih penting (1/7) | H20: Komunikasi lebih penting (7) | I20: Disposisi agak lebih penting (1/5) | J20: Sumber Daya sangat jauh lebih penting (9) | K20: Sama penting (1) | L20: Perempuan | N20: Jember | O20: Netral | P20: Penting | Q20: Netral | R20: Struktur birokrasi | S20: Penting | T20: Semua penting | V20: 1-6 bulan | W20: Nadhiahaphap@gmail.com | X20: Jateng | Y20: Fashion | Z20: S1
A21: 20 | B21: 45874.896 | D21: Mardianah rusli | E21: Owner | F21: Sumber Daya sangat jauh lebih penting (1/9) | G21: Disposisi sangat jauh lebih penting (1/9) | H21: Struktur Birokrasilebih penting (1/7) | I21: Sumber Daya sangat jauh lebih penting (9) | J21: Sumber Daya agak lebih penting (5) | K21: Sama penting (1) | L21: Perempuan | N21: Wajo | O21: Sangat Penting | P21: Sangat Penting | Q21: Sangat Penting | S21: Penting | V21: 1 tahun | W21: mardianahrusli226@gmail.com | X21: Sulawesi selatan | Y21: Abon Sapi & Abon ayam. | Z21: SMA
A22: 21 | B22: 45875.298 | D22: zainal Arifin | E22: wirasawasta | F22: Komunikasi lebih penting (7) | G22: Sama penting (1) | H22: Sama penting (1) | I22: Sama penting (1) | J22: Sama penting (1) | K22: Sama penting (1) | L22: Laki-laki | N22: Pinrang | O22: Netral | P22: Netral | Q22: Netral | R22: kesulitan dalam memastikan ketersediaan | S22: Netral | T22: ya karna dukungan pemerintah lebih penting dalam mencapai penghasilan | U22: tdk ada, | V22: 1-6 bulan | W22: lerang lerang | X22: sulawesi selatan | Y22: Bakso sapi , bkso ayam | Z22: SMA
A23: 22 | B23: 45875.597 | D23: JASLIN | E23: PELAKU USAHA | F23: Sumber Daya sangat jauh lebih penting (1/9) | G23: Komunikasi sangat jauh lebih penting (9) | H23: Komunikasi sangat jauh lebih penting (9) | I23: Sumber Daya sangat jauh lebih penting (9) | J23: Sumber Daya sangat jauh lebih penting (9) | K23: Disposisi sangat jauh lebih penting (9) | L23: Perempuan | N23: PINRANG | O23: Sangat Penting | P23: Sangat Penting | Q23: Sangat Penting | S23: Sangat Penting | V23: 1-6 bulan | W23: Barokah1740@gmail.com | X23: SULAWESI SELATAN | Y23: ABON | Z23: SMP
A24: 23 | B24: 45875.825 | D24: Pasha Anantha Apriliza | E24: Mahasiswa | F24: Komunikasi sangat jauh lebih penting (9) | G24: Sama penting (1) | H24: Sama penting (1) | I24: Sama penting (1) | J24: Sumber Daya sedikit lebih penting (3) | K24: Sama penting (1) | L24: Perempuan | N24: kab sukabumi | O24: Netral | P24: Sangat Penting | Q24: Sangat Penting | R24: Tantangan terbesar dalam implementasi JPH di Indonesia adalah ketidaksiapan struktur birokrasi dan sumber daya, yang diperparah oleh komunikasi yang tidak efektif dan komitmen pelaksana yang belum merata. Untuk menjawab tantangan ini dibutuhkan: Sosialisasi masif dan berkelanjutan Penguatan SDM auditor halal Kolaborasi lintas sektor yang lebih baik Reformasi birokrasi pelayanan halal (termasuk digitalisasi) | S24: Netral | T24: Komunikasi dan sumber daya adalah dua faktor paling penting dalam implementasi JPH di Indonesia. Tanpa keduanya, kebijakan ini sulit dipahami dan dilaksanakan secara efektif. Namun, disposisi dan struktur birokrasi tetap diperlukan sebagai penguat sistem secara keseluruhan. | U24: iya | V24: 1 tahun | W24: pashaananthaa@gmail.com | X24: jawab barat | Y24: F&B | Z24: SMA
A25: 24 | B25: 45875.892 | D25: Siti Asyri Masnawiyah | E25: Mahasiswa | F25: Sama penting (1) | G25: Sama penting (1) | H25: Sama penting (1) | I25: Sama penting (1) | J25: Sama penting (1) | K25: Sama penting (1) | L25: Perempuan | N25: Sukabumi | O25: Sangat Penting | P25: Sangat Penting | Q25: Sangat Penting | R25: Tantangan terbesar dalam implementasi Jaminan Produk Halal (JPH) di Indonesia mencakup kurangnya sosialisasi yang efektif kepada pelaku usaha, terutama UMKM, sehingga banyak yang belum memahami kewajiban sertifikasi halal. Selain itu, keterbatasan sumber daya manusia seperti auditor halal memperlambat proses sertifikasi. Dari sisi disposisi, masih terdapat resistensi dari pelaku usaha karena menganggap prosesnya rumit dan mahal. Struktur birokrasi yang berbelit dan lambat juga menjadi hambatan dalam mewujudkan layanan JPH yang efisien dan merata. | S25: Sangat Penting | T25: Ya, dalam konteks implementasi JPH di Indonesia, faktor komunikasi dan sumber daya manusia bisa dianggap lebih penting dibandingkan yang lain. Komunikasi yang efektif sangat krusial karena banyak pelaku usaha, khususnya UMKM, belum memahami pentingnya sertifikasi halal dan prosedurnya. Tanpa pemahaman yang memadai, kepatuhan akan rendah. Selain itu, ketersediaan sumber daya manusia seperti auditor halal dan penyuluh sangat menentukan kelancaran proses sertifikasi. Tanpa SDM yang cukup dan kompeten, proses akan lambat meskipun sistem dan regulasi sudah ada. Faktor-faktor ini menjadi fondasi bagi keberhasilan implementasi JPH secara menyeluruh. | U25: Ya, salah satu faktor penting yang juga memengaruhi keberhasilan implementasi JPH namun tidak tercakup dalam kriteria di atas adalah dukungan politik dan regulasi yang konsisten. Kebijakan pemerintah yang kuat, harmonisasi regulasi antarinstansi, serta komitmen politik dari pusat hingga daerah sangat menentukan arah dan keberlanjutan program JPH. Selain itu, partisipasi aktif masyarakat dan lembaga keagamaan juga berperan besar dalam membangun kesadaran dan kepercayaan terhadap pentingnya produk halal. Tanpa dukungan ini, implementasi JPH berisiko stagnan meskipun faktor teknis lainnya terpenuhi. | V25: 1-6 bulan | W25: masnawh@gmail.com | X25: Jawa Barat | Y25: Basreng renyah | Z25: SMA
A26: 25 | B26: 45875.901 | D26: Muhamad fiqri | E26: Mahasiswa | F26: Komunikasi sangat jauh lebih penting (9) | G26: Komunikasi lebih penting (7) | H26: Komunikasi agak lebih penting (5) | I26: Sama penting (1) | J26: Sumber Daya sedikit lebih penting (3) | K26: Struktur Birokrasi sedikit lebih penting (1/3) | L26: Laki-laki | N26: Sukabumi | O26: Netral | P26: Tidak Penting | Q26: Tidak Penting | R26: Kurangnya literasi dari masyarakat | S26: Sangat Penting | T26: Ada .. | U26: Tidak ada | V26: 1-6 bulan | W26: mhmdfikri968@gmail.com | X26: Jawa barat | Y26: Kantin sehat | Z26: SMA
A27: 26 | B27: 45875.904 | D27: Elsa Elyanti Suherman | E27: Mahasiswa | F27: Sumber Daya sangat jauh lebih penting (1/9) | G27: Komunikasi sangat jauh lebih penting (9) | H27: Sama penting (1) | I27: Sumber Daya lebih penting (7) | J27: Struktur Birokrasi lebih penting (1/7) | K27: Sama penting (1) | L27: Perempuan | N27: Kota Sukabumi | O27: Sangat Penting | P27: Sangat Penting | Q27: Sangat Penting | R27: Tantangan utama implementasi JPH di Indonesia meliputi komunikasi yang kurang merata, terbatasnya auditor dan fasilitas halal, rendahnya komitmen pelaksana, serta birokrasi yang rumit dan lamban. | S27: Sangat Penting | T27: Ya, faktor sumber daya merupakan yang paling krusial dalam implementasi JPH di Indonesia. Tanpa auditor halal yang memadai dan fasilitas pendukung seperti laboratorium yang tersebar merata, proses sertifikasi menjadi lambat dan tidak merata. Meskipun komunikasi dan struktur birokrasi penting, kekurangan sumber daya langsung menghambat pelaksanaan teknis di lapangan, terutama di daerah terpencil dan bagi pelaku UMKM. | U27: Ya, salah satu faktor penting yang juga memengaruhi keberhasilan implementasi JPH namun sering luput dari perhatian adalah kesadaran dan partisipasi masyarakat. Tanpa adanya permintaan dan dorongan dari konsumen terhadap produk halal, pelaku usaha akan kurang terdorong untuk mengurus sertifikasi. Kesadaran konsumen tentang pentingnya produk halal dapat menjadi pendorong kuat agar seluruh ekosistem JPH berjalan efektif, terutama dalam mendorong pelaku usaha untuk patuh terhadap regulasi. | V27: 1 tahun | W27: eelyanti5@gmail.com | X27: Jawa Barat | Y27: Seblak | Z27: S1
